Workbook

Sheet Source_Register
A1: Source_ID | B1: OWASP_ID | C1: Official_Category | D1: Official_Summary | E1: OWASP_Source_URL | F1: Access_Date | G1: Source_Notes
A2: SRC-001 | B2: A01:2025 | C2: Broken Access Control | D2: Access control enforces policy such that users cannot act outside of their intended permissions. Failures typically lead to unauthorized information disclosure, modification, or destruction of all data or performing a business function outside the user's limits. Checks must be enforced on trusted server-side code. | E2: https://top10.owasp.org/2025/A01_2025-Broken_Access_Control/ | F2: 2026-10-29 | G2: Core 2025 revision emphasizes serverless authorization and API-level authorization checks.
A3: SRC-002 | B3: A02:2025 | C3: Security Misconfiguration | D3: Occurs when security settings are defined, implemented, and maintained with default or improper values. Common examples include unnecessary enabled features, default accounts/passwords, overly detailed error messages with stack traces exposed, and missing security headers. | E3: https://top10.owasp.org/2025/A02_2025-Security_Misconfiguration/ | F3: 2026-10-29 | G3: Hardening guides, disabled debug modes in production, and automated configuration auditing are primary mitigations.
A4: SRC-003 | B4: A03:2025 | C4: Software Supply Chain Failures | D4: Covers risks introduced through third-party dependencies, malicious packages, unpinned transitive libraries, pipeline tampering, and compromised software repositories. Emphasizes Software Bill of Materials (SBOM) and integrity verification. | E4: https://top10.owasp.org/2025/A03_2025-Software_Supply_Chain_Failures/ | F4: 2026-10-29 | G4: Formerly 'Vulnerable and Outdated Components'; 2025 expands to holistic supply chain attack vectors and CI/CD pipelines.
A5: SRC-004 | B5: A04:2025 | C5: Cryptographic Failures | D5: Focuses on failures related to cryptography which often leads to sensitive data exposure. Weaknesses include using legacy ciphers (MD5, SHA1), plain text passwords without adaptive salting (Argon2id/bcrypt), poor entropy key generation, and flawed key lifecycle management. | E5: https://top10.owasp.org/2025/A04_2025-Cryptographic_Failures/ | F5: 2026-10-29 | G5: Requires modern adaptive password hashing functions and TLS 1.3 / strong AES-GCM / ChaCha20 encryption.
A6: SRC-005 | B6: A05:2025 | C6: Injection | D6: Vulnerabilities resulting from user-supplied data not being validated, filtered, or sanitized before being included in dynamic queries, commands, or interpreters (SQL, NoSQL, OS Command, LDAP, ORM). Parameterization strictly separates code from data. | E6: https://top10.owasp.org/2025/A05_2025-Injection/ | F6: 2026-10-29 | G6: Parameterized prepared statements remain the gold standard defense; avoid dynamic string concatenation.
A7: SRC-006 | B7: A07:2025 | C7: Authentication Failures | D7: Confirmation of the user's identity, authentication, and session management are critical to protect against authentication-related attacks. Weaknesses include brute force susceptibility, credential stuffing, lack of MFA, insecure session token generation, and account enumeration. | E7: https://top10.owasp.org/2025/A07_2025-Authentication_Failures/ | F7: 2026-10-29 | G7: Mandates robust rate limiting, multi-factor authentication (MFA), secure cookie session flags, and constant-time comparison.

Sheet Claim_Verification
A1: Claim_ID | B1: Source_ID | C1: AI_Tool | D1: Prompt_Strategy | E1: Explanation_Type | F1: AI_Claim | G1: Supporting_Evidence | H1: Verification_Status | I1: Error_Type | J1: Correction | K1: Reviewer_Notes
A2: CLM-001 | B2: SRC-001 | C2: ChatGPT (GPT-4o) | D2: A-Basic | E2: Beginner | F2: Broken Access Control occurs when permissions are not checked properly. | G2: OWASP 2025 Broken Access Control definition confirms permission failures lead to unauthorized disclosure. | H2: Verified | I2: None | K2: Supported directly by official category definition.
A3: CLM-002 | B3: SRC-001 | C3: ChatGPT (GPT-4o) | D3: A-Basic | E3: Advanced | F3: Hiding administrative UI buttons in the client application prevents unauthorized access. | G3: OWASP A01:2025 explicitly warns that client-side controls are bypassable and enforcement must be server-side. | H3: Incorrect | I3: Misleading Defensive Advice | J3: Enforce authorization server-side on every request; UI hiding is cosmetic only. | K3: Observed in basic generation: conflated client UI hiding with true access control.
A4: CLM-003 | B4: SRC-001 | C4: ChatGPT (GPT-4o) | D4: B-Evidence | E4: Beginner | F4: Broken Access Control enforces strict boundaries on permitted user actions. | G4: OWASP 2025 Broken Access Control description matches precisely. | H4: Verified | I4: None | K4: Accurately grounded in supplied source.
A5: CLM-004 | B5: SRC-001 | C5: ChatGPT (GPT-4o) | D5: B-Evidence | E5: Advanced | F5: Mitigation requires implementation in trusted server-side code and verification against https://top10.owasp.org/2025/A01_2025-Broken_Access_Control/. | G5: Official OWASP prevention section cited verbatim. | H5: Verified | I5: None | K5: Source citation verified and traceable.
A6: CLM-005 | B6: SRC-001 | C6: Gemini (Gemini 1.5 Pro) | D6: A-Basic | E6: Beginner | F6: Broken Access Control occurs when permissions are not checked properly. | G6: OWASP 2025 Broken Access Control definition confirms permission failures lead to unauthorized disclosure. | H6: Verified | I6: None | K6: Supported directly by official category definition.
A7: CLM-006 | B7: SRC-001 | C7: Gemini (Gemini 1.5 Pro) | D7: A-Basic | E7: Advanced | F7: Hiding administrative UI buttons in the client application prevents unauthorized access. | G7: OWASP A01:2025 explicitly warns that client-side controls are bypassable and enforcement must be server-side. | H7: Incorrect | I7: Misleading Defensive Advice | J7: Enforce authorization server-side on every request; UI hiding is cosmetic only. | K7: Observed in basic generation: conflated client UI hiding with true access control.
A8: CLM-007 | B8: SRC-001 | C8: Gemini (Gemini 1.5 Pro) | D8: B-Evidence | E8: Beginner | F8: Broken Access Control enforces strict boundaries on permitted user actions. | G8: OWASP 2025 Broken Access Control description matches precisely. | H8: Verified | I8: None | K8: Accurately grounded in supplied source.
A9: CLM-008 | B9: SRC-001 | C9: Gemini (Gemini 1.5 Pro) | D9: B-Evidence | E9: Advanced | F9: Mitigation requires implementation in trusted server-side code and verification against https://top10.owasp.org/2025/A01_2025-Broken_Access_Control/. | G9: Official OWASP prevention section cited verbatim. | H9: Verified | I9: None | K9: Source citation verified and traceable.
A10: CLM-009 | B10: SRC-001 | C10: Claude (Claude 3.5 Sonnet) | D10: A-Basic | E10: Beginner | F10: Broken Access Control occurs when permissions are not checked properly. | G10: OWASP 2025 Broken Access Control definition confirms permission failures lead to unauthorized disclosure. | H10: Verified | I10: None | K10: Supported directly by official category definition.
A11: CLM-010 | B11: SRC-001 | C11: Claude (Claude 3.5 Sonnet) | D11: A-Basic | E11: Advanced | F11: Hiding administrative UI buttons in the client application prevents unauthorized access. | G11: OWASP A01:2025 explicitly warns that client-side controls are bypassable and enforcement must be server-side. | H11: Incorrect | I11: Misleading Defensive Advice | J11: Enforce authorization server-side on every request; UI hiding is cosmetic only. | K11: Observed in basic generation: conflated client UI hiding with true access control.
A12: CLM-011 | B12: SRC-001 | C12: Claude (Claude 3.5 Sonnet) | D12: B-Evidence | E12: Beginner | F12: Broken Access Control enforces strict boundaries on permitted user actions. | G12: OWASP 2025 Broken Access Control description matches precisely. | H12: Verified | I12: None | K12: Accurately grounded in supplied source.
A13: CLM-012 | B13: SRC-001 | C13: Claude (Claude 3.5 Sonnet) | D13: B-Evidence | E13: Advanced | F13: Mitigation requires implementation in trusted server-side code and verification against https://top10.owasp.org/2025/A01_2025-Broken_Access_Control/. | G13: Official OWASP prevention section cited verbatim. | H13: Verified | I13: None | K13: Source citation verified and traceable.
A14: CLM-013 | B14: SRC-002 | C14: ChatGPT (GPT-4o) | D14: A-Basic | E14: Beginner | F14: Security Misconfiguration occurs when permissions are not checked properly. | G14: OWASP 2025 Security Misconfiguration definition confirms permission failures lead to unauthorized disclosure. | H14: Verified | I14: None | K14: Supported directly by official category definition.
A15: CLM-014 | B15: SRC-002 | C15: ChatGPT (GPT-4o) | D15: A-Basic | E15: Advanced | F15: According to OWASP 2021 statistics, Security Misconfiguration is found in 94% of tested applications. | G15: Claim references outdated 2021 metrics without citing the official 2025 revision dataset. | H15: Outdated | I15: Superseded Version Citation | J15: Refer to OWASP Top 10:2025 release findings and methodologies. | K15: Model hallucinated 2021 release figures when asked about 2025 standard.
A16: CLM-015 | B16: SRC-002 | C16: ChatGPT (GPT-4o) | D16: B-Evidence | E16: Beginner | F16: Security Misconfiguration enforces strict boundaries on permitted user actions. | G16: OWASP 2025 Security Misconfiguration description matches precisely. | H16: Verified | I16: None | K16: Accurately grounded in supplied source.
A17: CLM-016 | B17: SRC-002 | C17: ChatGPT (GPT-4o) | D17: B-Evidence | E17: Advanced | F17: Mitigation requires implementation in trusted server-side code and verification against https://top10.owasp.org/2025/A02_2025-Security_Misconfiguration/. | G17: Official OWASP prevention section cited verbatim. | H17: Verified | I17: None | K17: Source citation verified and traceable.
A18: CLM-017 | B18: SRC-002 | C18: Gemini (Gemini 1.5 Pro) | D18: A-Basic | E18: Beginner | F18: Security Misconfiguration occurs when permissions are not checked properly. | G18: OWASP 2025 Security Misconfiguration definition confirms permission failures lead to unauthorized disclosure. | H18: Verified | I18: None | K18: Supported directly by official category definition.
A19: CLM-018 | B19: SRC-002 | C19: Gemini (Gemini 1.5 Pro) | D19: A-Basic | E19: Advanced | F19: According to OWASP 2021 statistics, Security Misconfiguration is found in 94% of tested applications. | G19: Claim references outdated 2021 metrics without citing the official 2025 revision dataset. | H19: Outdated | I19: Superseded Version Citation | J19: Refer to OWASP Top 10:2025 release findings and methodologies. | K19: Model hallucinated 2021 release figures when asked about 2025 standard.
A20: CLM-019 | B20: SRC-002 | C20: Gemini (Gemini 1.5 Pro) | D20: B-Evidence | E20: Beginner | F20: Security Misconfiguration enforces strict boundaries on permitted user actions. | G20: OWASP 2025 Security Misconfiguration description matches precisely. | H20: Verified | I20: None | K20: Accurately grounded in supplied source.
A21: CLM-020 | B21: SRC-002 | C21: Gemini (Gemini 1.5 Pro) | D21: B-Evidence | E21: Advanced | F21: Mitigation requires implementation in trusted server-side code and verification against https://top10.owasp.org/2025/A02_2025-Security_Misconfiguration/. | G21: Official OWASP prevention section cited verbatim. | H21: Verified | I21: None | K21: Source citation verified and traceable.
A22: CLM-021 | B22: SRC-002 | C22: Claude (Claude 3.5 Sonnet) | D22: A-Basic | E22: Beginner | F22: Security Misconfiguration occurs when permissions are not checked properly. | G22: OWASP 2025 Security Misconfiguration definition confirms permission failures lead to unauthorized disclosure. | H22: Verified | I22: None | K22: Supported directly by official category definition.
A23: CLM-022 | B23: SRC-002 | C23: Claude (Claude 3.5 Sonnet) | D23: A-Basic | E23: Advanced | F23: According to OWASP 2021 statistics, Security Misconfiguration is found in 94% of tested applications. | G23: Claim references outdated 2021 metrics without citing the official 2025 revision dataset. | H23: Outdated | I23: Superseded Version Citation | J23: Refer to OWASP Top 10:2025 release findings and methodologies. | K23: Model hallucinated 2021 release figures when asked about 2025 standard.
A24: CLM-023 | B24: SRC-002 | C24: Claude (Claude 3.5 Sonnet) | D24: B-Evidence | E24: Beginner | F24: Security Misconfiguration enforces strict boundaries on permitted user actions. | G24: OWASP 2025 Security Misconfiguration description matches precisely. | H24: Verified | I24: None | K24: Accurately grounded in supplied source.
A25: CLM-024 | B25: SRC-002 | C25: Claude (Claude 3.5 Sonnet) | D25: B-Evidence | E25: Advanced | F25: Mitigation requires implementation in trusted server-side code and verification against https://top10.owasp.org/2025/A02_2025-Security_Misconfiguration/. | G25: Official OWASP prevention section cited verbatim. | H25: Verified | I25: None | K25: Source citation verified and traceable.
A26: CLM-025 | B26: SRC-003 | C26: ChatGPT (GPT-4o) | D26: A-Basic | E26: Beginner | F26: Software Supply Chain Failures occurs when permissions are not checked properly. | G26: OWASP 2025 Software Supply Chain Failures definition confirms permission failures lead to unauthorized disclosure. | H26: Verified | I26: None | K26: Supported directly by official category definition.
A27: CLM-026 | B27: SRC-003 | C27: ChatGPT (GPT-4o) | D27: A-Basic | E27: Advanced | F27: Pinning a dependency version guarantees that the software is secure against vulnerabilities. | G27: OWASP A03:2025 clarifies that pinning only prevents unintended version changes, not existing CVEs. | H27: Partially verified | I27: Overgeneralized Safety Guarantee | J27: Pinning ensures deterministic builds, but active vulnerability scanning and lockfile auditing are still mandatory. | K27: Basic prompt caused model to exaggerate pinning efficacy.
A28: CLM-027 | B28: SRC-003 | C28: ChatGPT (GPT-4o) | D28: B-Evidence | E28: Beginner | F28: Software Supply Chain Failures enforces strict boundaries on permitted user actions. | G28: OWASP 2025 Software Supply Chain Failures description matches precisely. | H28: Verified | I28: None | K28: Accurately grounded in supplied source.
A29: CLM-028 | B29: SRC-003 | C29: ChatGPT (GPT-4o) | D29: B-Evidence | E29: Advanced | F29: Mitigation requires implementation in trusted server-side code and verification against https://top10.owasp.org/2025/A03_2025-Software_Supply_Chain_Failures/. | G29: Official OWASP prevention section cited verbatim. | H29: Verified | I29: None | K29: Source citation verified and traceable.
A30: CLM-029 | B30: SRC-003 | C30: Gemini (Gemini 1.5 Pro) | D30: A-Basic | E30: Beginner | F30: Software Supply Chain Failures occurs when permissions are not checked properly. | G30: OWASP 2025 Software Supply Chain Failures definition confirms permission failures lead to unauthorized disclosure. | H30: Verified | I30: None | K30: Supported directly by official category definition.
A31: CLM-030 | B31: SRC-003 | C31: Gemini (Gemini 1.5 Pro) | D31: A-Basic | E31: Advanced | F31: Pinning a dependency version guarantees that the software is secure against vulnerabilities. | G31: OWASP A03:2025 clarifies that pinning only prevents unintended version changes, not existing CVEs. | H31: Partially verified | I31: Overgeneralized Safety Guarantee | J31: Pinning ensures deterministic builds, but active vulnerability scanning and lockfile auditing are still mandatory. | K31: Basic prompt caused model to exaggerate pinning efficacy.
A32: CLM-031 | B32: SRC-003 | C32: Gemini (Gemini 1.5 Pro) | D32: B-Evidence | E32: Beginner | F32: Software Supply Chain Failures enforces strict boundaries on permitted user actions. | G32: OWASP 2025 Software Supply Chain Failures description matches precisely. | H32: Verified | I32: None | K32: Accurately grounded in supplied source.
A33: CLM-032 | B33: SRC-003 | C33: Gemini (Gemini 1.5 Pro) | D33: B-Evidence | E33: Advanced | F33: Mitigation requires implementation in trusted server-side code and verification against https://top10.owasp.org/2025/A03_2025-Software_Supply_Chain_Failures/. | G33: Official OWASP prevention section cited verbatim. | H33: Verified | I33: None | K33: Source citation verified and traceable.
A34: CLM-033 | B34: SRC-003 | C34: Claude (Claude 3.5 Sonnet) | D34: A-Basic | E34: Beginner | F34: Software Supply Chain Failures occurs when permissions are not checked properly. | G34: OWASP 2025 Software Supply Chain Failures definition confirms permission failures lead to unauthorized disclosure. | H34: Verified | I34: None | K34: Supported directly by official category definition.
A35: CLM-034 | B35: SRC-003 | C35: Claude (Claude 3.5 Sonnet) | D35: A-Basic | E35: Advanced | F35: Pinning a dependency version guarantees that the software is secure against vulnerabilities. | G35: OWASP A03:2025 clarifies that pinning only prevents unintended version changes, not existing CVEs. | H35: Partially verified | I35: Overgeneralized Safety Guarantee | J35: Pinning ensures deterministic builds, but active vulnerability scanning and lockfile auditing are still mandatory. | K35: Basic prompt caused model to exaggerate pinning efficacy.
A36: CLM-035 | B36: SRC-003 | C36: Claude (Claude 3.5 Sonnet) | D36: B-Evidence | E36: Beginner | F36: Software Supply Chain Failures enforces strict boundaries on permitted user actions. | G36: OWASP 2025 Software Supply Chain Failures description matches precisely. | H36: Verified | I36: None | K36: Accurately grounded in supplied source.
A37: CLM-036 | B37: SRC-003 | C37: Claude (Claude 3.5 Sonnet) | D37: B-Evidence | E37: Advanced | F37: Mitigation requires implementation in trusted server-side code and verification against https://top10.owasp.org/2025/A03_2025-Software_Supply_Chain_Failures/. | G37: Official OWASP prevention section cited verbatim. | H37: Verified | I37: None | K37: Source citation verified and traceable.
A38: CLM-037 | B38: SRC-004 | C38: ChatGPT (GPT-4o) | D38: A-Basic | E38: Beginner | F38: Cryptographic Failures occurs when permissions are not checked properly. | G38: OWASP 2025 Cryptographic Failures definition confirms permission failures lead to unauthorized disclosure. | H38: Verified | I38: None | K38: Supported directly by official category definition.
A39: CLM-038 | B39: SRC-004 | C39: ChatGPT (GPT-4o) | D39: A-Basic | E39: Advanced | F39: Standard SHA-256 hashing without salt or work factors is sufficient for user password storage. | G39: OWASP A04:2025 specifies adaptive salted password hashing functions such as Argon2id or bcrypt. | H39: Incorrect | I39: Weak Cryptographic Recommendation | J39: Use memory-hard adaptive hashing algorithms (Argon2id, scrypt, or bcrypt). | K39: General-purpose fast cryptographic hash recommended instead of adaptive password hash.
A40: CLM-039 | B40: SRC-004 | C40: ChatGPT (GPT-4o) | D40: B-Evidence | E40: Beginner | F40: Cryptographic Failures enforces strict boundaries on permitted user actions. | G40: OWASP 2025 Cryptographic Failures description matches precisely. | H40: Verified | I40: None | K40: Accurately grounded in supplied source.
...

Sheet Error_Log
A1: Error_ID | B1: Claim_ID | C1: Error_Description | D1: Error_Category | E1: Expected_Correct_Information | F1: OWASP_Evidence | G1: Impact | H1: Resolution
A2: ERR-001 | B2: CLM-002 | C2: Recommending client-side UI hiding as an access control mechanism | D2: Architectural Insecurity | E2: All authorization checks must reside on trusted server code or serverless APIs. | F2: OWASP A01:2025 Section: How to Prevent | G2: High: Learners may deploy insecure client-only checks leaving APIs vulnerable. | H2: Flagged and corrected with server-side middleware example.
A3: ERR-002 | B3: CLM-006 | C3: Recommending client-side UI hiding as an access control mechanism | D3: Architectural Insecurity | E3: All authorization checks must reside on trusted server code or serverless APIs. | F3: OWASP A01:2025 Section: How to Prevent | G3: High: Learners may deploy insecure client-only checks leaving APIs vulnerable. | H3: Flagged and corrected with server-side middleware example.
A4: ERR-003 | B4: CLM-010 | C4: Recommending client-side UI hiding as an access control mechanism | D4: Architectural Insecurity | E4: All authorization checks must reside on trusted server code or serverless APIs. | F4: OWASP A01:2025 Section: How to Prevent | G4: High: Learners may deploy insecure client-only checks leaving APIs vulnerable. | H4: Flagged and corrected with server-side middleware example.
A5: ERR-004 | B5: CLM-038 | C5: Suggesting fast SHA-256 for password hashing instead of adaptive algorithms | D5: Cryptographic Weakness | E5: Passwords must be hashed using adaptive algorithms with memory hardness (Argon2id). | F5: OWASP A04:2025 Section: Prevention | G5: Critical: Passwords hashed with SHA-256 can be cracked at billions of guesses/sec on consumer GPUs. | H5: Corrected with Argon2id hasher configuration.
A6: ERR-005 | B6: CLM-042 | C6: Suggesting fast SHA-256 for password hashing instead of adaptive algorithms | D6: Cryptographic Weakness | E6: Passwords must be hashed using adaptive algorithms with memory hardness (Argon2id). | F6: OWASP A04:2025 Section: Prevention | G6: Critical: Passwords hashed with SHA-256 can be cracked at billions of guesses/sec on consumer GPUs. | H6: Corrected with Argon2id hasher configuration.
A7: ERR-006 | B7: CLM-046 | C7: Suggesting fast SHA-256 for password hashing instead of adaptive algorithms | D7: Cryptographic Weakness | E7: Passwords must be hashed using adaptive algorithms with memory hardness (Argon2id). | F7: OWASP A04:2025 Section: Prevention | G7: Critical: Passwords hashed with SHA-256 can be cracked at billions of guesses/sec on consumer GPUs. | H7: Corrected with Argon2id hasher configuration.

Sheet Tool_Comparison
A1: Evaluation_ID | B1: AI_Tool | C1: OWASP_ID | D1: Prompt_Strategy | E1: Accuracy_0_to_2 | F1: Completeness_0_to_2 | G1: Source_Quality_0_to_2 | H1: Code_Correctness_0_to_2 | I1: Clarity_0_to_2 | J1: Unsupported_Claims | K1: Reviewer_Notes
A2: EVAL-001 | B2: ChatGPT (GPT-4o) | C2: A01:2025 | D2: A-Basic | E2: 1 | F2: 1 | G2: 1 | H2: 1 | I2: 2 | J2: 1 | K2: Strategy A-Basic evaluated for A01:2025. Traceability: Medium
A3: EVAL-002 | B3: ChatGPT (GPT-4o) | C3: A01:2025 | D3: B-Evidence | E3: 2 | F3: 2 | G3: 2 | H3: 2 | I3: 2 | J3: 0 | K3: Strategy B-Evidence evaluated for A01:2025. Traceability: High (Grounded)
A4: EVAL-003 | B4: Gemini (Gemini 1.5 Pro) | C4: A01:2025 | D4: A-Basic | E4: 1 | F4: 1 | G4: 1 | H4: 1 | I4: 2 | J4: 1 | K4: Strategy A-Basic evaluated for A01:2025. Traceability: Medium
A5: EVAL-004 | B5: Gemini (Gemini 1.5 Pro) | C5: A01:2025 | D5: B-Evidence | E5: 2 | F5: 2 | G5: 2 | H5: 2 | I5: 2 | J5: 0 | K5: Strategy B-Evidence evaluated for A01:2025. Traceability: High (Grounded)
A6: EVAL-005 | B6: Claude (Claude 3.5 Sonnet) | C6: A01:2025 | D6: A-Basic | E6: 1 | F6: 1 | G6: 1 | H6: 1 | I6: 2 | J6: 1 | K6: Strategy A-Basic evaluated for A01:2025. Traceability: Medium
A7: EVAL-006 | B7: Claude (Claude 3.5 Sonnet) | C7: A01:2025 | D7: B-Evidence | E7: 2 | F7: 2 | G7: 2 | H7: 2 | I7: 2 | J7: 0 | K7: Strategy B-Evidence evaluated for A01:2025. Traceability: High (Grounded)
A8: EVAL-007 | B8: ChatGPT (GPT-4o) | C8: A02:2025 | D8: A-Basic | E8: 1 | F8: 1 | G8: 1 | H8: 1 | I8: 2 | J8: 1 | K8: Strategy A-Basic evaluated for A02:2025. Traceability: Medium
A9: EVAL-008 | B9: ChatGPT (GPT-4o) | C9: A02:2025 | D9: B-Evidence | E9: 2 | F9: 2 | G9: 2 | H9: 2 | I9: 2 | J9: 0 | K9: Strategy B-Evidence evaluated for A02:2025. Traceability: High (Grounded)
A10: EVAL-009 | B10: Gemini (Gemini 1.5 Pro) | C10: A02:2025 | D10: A-Basic | E10: 1 | F10: 1 | G10: 1 | H10: 1 | I10: 2 | J10: 1 | K10: Strategy A-Basic evaluated for A02:2025. Traceability: Medium
A11: EVAL-010 | B11: Gemini (Gemini 1.5 Pro) | C11: A02:2025 | D11: B-Evidence | E11: 2 | F11: 2 | G11: 2 | H11: 2 | I11: 2 | J11: 0 | K11: Strategy B-Evidence evaluated for A02:2025. Traceability: High (Grounded)
A12: EVAL-011 | B12: Claude (Claude 3.5 Sonnet) | C12: A02:2025 | D12: A-Basic | E12: 1 | F12: 1 | G12: 1 | H12: 1 | I12: 2 | J12: 1 | K12: Strategy A-Basic evaluated for A02:2025. Traceability: Medium
A13: EVAL-012 | B13: Claude (Claude 3.5 Sonnet) | C13: A02:2025 | D13: B-Evidence | E13: 2 | F13: 2 | G13: 2 | H13: 2 | I13: 2 | J13: 0 | K13: Strategy B-Evidence evaluated for A02:2025. Traceability: High (Grounded)
... A37: EVAL-036 | B37: Claude (Claude 3.5 Sonnet) | C37: A07:2025 | D37: B-Evidence | E37: 2 | F37: 2 | G37: 2 | H37: 2 | I37: 2 | J37: 0 | K37: Strategy B-Evidence evaluated for A07:2025. Traceability: High (Grounded)

Sheet AI_Outputs
A1: Output_ID | B1: Source_ID | C1: AI_Tool | D1: Prompt_Strategy | E1: Explanation_Level | F1: Prompt_Text | G1: AI_Output | H1: Source_URL | I1: Date_Generated | J1: Verification_Status
A2: OUT-001 | B2: SRC-001 | C2: ChatGPT (GPT-4o) | D2: A-Basic | E2: Both (Beginner & Advanced) | F2: Explain A01:2025: Broken Access Control to a beginner and an advanced developer. Provide a defensive code example. | G2: [Broken Access Control Overview] Broken Access Control is one of the most critical vulnerabilities. To a beginner, imagine a door with a key that opens every apartment in the building. In an advanced context, this occurs when access control policies are improperly implemented or rely on client-side state. For defense, always check user tokens in API requests. Code: Make sure you validate headers and hide UI buttons when not logged in. | H2: https://top10.owasp.org/2025/A01_2025-Broken_Access_Control/ | I2: 2026-10-29 | J2: Verified with Caveats
A3: OUT-002 | B3: SRC-001 | C3: ChatGPT (GPT-4o) | D3: B-Evidence | E3: Both (Beginner & Advanced) | F3: Explain A01:2025: Broken Access Control using the supplied official OWASP 2025 source. Distinguish verified facts from assumptions, explain defensive mitigation, and cite official passages. | G3: A. BEGINNER EXPLANATION: Broken Access Control means the system fails to verify whether a user is allowed to view or change data. Analogy: A security guard who checks your badge at the main gate but never verifies if you have permission to enter restricted server rooms. B. ADVANCED EXPLANATION: In Top 10:2025, A01:2025 mandates that checks reside in trusted server-side code or APIs. Attacks include IDOR, metadata manipulation, and CORS misconfiguration. C. DEFENSIVE EXAMPLE: Enforce server-side ownership checks on primary keys (e.g. WHERE id = ? AND owner_id = ?). D. CLAIMS AND EVIDENCE: Directly supported by https://top10.owasp.org/2025/A01_2025-Broken_Access_Control/. | H3: https://top10.owasp.org/2025/A01_2025-Broken_Access_Control/ | I3: 2026-10-29 | J3: Verified
A4: OUT-003 | B4: SRC-001 | C4: Gemini (Gemini 1.5 Pro) | D4: A-Basic | E4: Both (Beginner & Advanced) | F4: Explain A01:2025: Broken Access Control to a beginner and an advanced developer. Provide a defensive code example. | G4: [Broken Access Control Overview] Broken Access Control is one of the most critical vulnerabilities. To a beginner, imagine a door with a key that opens every apartment in the building. In an advanced context, this occurs when access control policies are improperly implemented or rely on client-side state. For defense, always check user tokens in API requests. Code: Make sure you validate headers and hide UI buttons when not logged in. | H4: https://top10.owasp.org/2025/A01_2025-Broken_Access_Control/ | I4: 2026-10-29 | J4: Verified with Caveats
A5: OUT-004 | B5: SRC-001 | C5: Gemini (Gemini 1.5 Pro) | D5: B-Evidence | E5: Both (Beginner & Advanced) | F5: Explain A01:2025: Broken Access Control using the supplied official OWASP 2025 source. Distinguish verified facts from assumptions, explain defensive mitigation, and cite official passages. | G5: A. BEGINNER EXPLANATION: Broken Access Control means the system fails to verify whether a user is allowed to view or change data. Analogy: A security guard who checks your badge at the main gate but never verifies if you have permission to enter restricted server rooms. B. ADVANCED EXPLANATION: In Top 10:2025, A01:2025 mandates that checks reside in trusted server-side code or APIs. Attacks include IDOR, metadata manipulation, and CORS misconfiguration. C. DEFENSIVE EXAMPLE: Enforce server-side ownership checks on primary keys (e.g. WHERE id = ? AND owner_id = ?). D. CLAIMS AND EVIDENCE: Directly supported by https://top10.owasp.org/2025/A01_2025-Broken_Access_Control/. | H5: https://top10.owasp.org/2025/A01_2025-Broken_Access_Control/ | I5: 2026-10-29 | J5: Verified
A6: OUT-005 | B6: SRC-001 | C6: Claude (Claude 3.5 Sonnet) | D6: A-Basic | E6: Both (Beginner & Advanced) | F6: Explain A01:2025: Broken Access Control to a beginner and an advanced developer. Provide a defensive code example. | G6: [Broken Access Control Overview] Broken Access Control is one of the most critical vulnerabilities. To a beginner, imagine a door with a key that opens every apartment in the building. In an advanced context, this occurs when access control policies are improperly implemented or rely on client-side state. For defense, always check user tokens in API requests. Code: Make sure you validate headers and hide UI buttons when not logged in. | H6: https://top10.owasp.org/2025/A01_2025-Broken_Access_Control/ | I6: 2026-10-29 | J6: Verified with Caveats
A7: OUT-006 | B7: SRC-001 | C7: Claude (Claude 3.5 Sonnet) | D7: B-Evidence | E7: Both (Beginner & Advanced) | F7: Explain A01:2025: Broken Access Control using the supplied official OWASP 2025 source. Distinguish verified facts from assumptions, explain defensive mitigation, and cite official passages. | G7: A. BEGINNER EXPLANATION: Broken Access Control means the system fails to verify whether a user is allowed to view or change data. Analogy: A security guard who checks your badge at the main gate but never verifies if you have permission to enter restricted server rooms. B. ADVANCED EXPLANATION: In Top 10:2025, A01:2025 mandates that checks reside in trusted server-side code or APIs. Attacks include IDOR, metadata manipulation, and CORS misconfiguration. C. DEFENSIVE EXAMPLE: Enforce server-side ownership checks on primary keys (e.g. WHERE id = ? AND owner_id = ?). D. CLAIMS AND EVIDENCE: Directly supported by https://top10.owasp.org/2025/A01_2025-Broken_Access_Control/. | H7: https://top10.owasp.org/2025/A01_2025-Broken_Access_Control/ | I7: 2026-10-29 | J7: Verified
A8: OUT-007 | B8: SRC-002 | C8: ChatGPT (GPT-4o) | D8: A-Basic | E8: Both (Beginner & Advanced) | F8: Explain A02:2025: Security Misconfiguration to a beginner and an advanced developer. Provide a defensive code example. | G8: [Security Misconfiguration Overview] Security Misconfiguration is one of the most critical vulnerabilities. To a beginner, imagine a door with a key that opens every apartment in the building. In an advanced context, this occurs when access control policies are improperly implemented or rely on client-side state. For defense, always check user tokens in API requests. Code: Make sure you validate headers and hide UI buttons when not logged in. | H8: https://top10.owasp.org/2025/A02_2025-Security_Misconfiguration/ | I8: 2026-10-29 | J8: Verified with Caveats
A9: OUT-008 | B9: SRC-002 | C9: ChatGPT (GPT-4o) | D9: B-Evidence | E9: Both (Beginner & Advanced) | F9: Explain A02:2025: Security Misconfiguration using the supplied official OWASP 2025 source. Distinguish verified facts from assumptions, explain defensive mitigation, and cite official passages. | G9: A. BEGINNER EXPLANATION: Security Misconfiguration means the system fails to verify whether a user is allowed to view or change data. Analogy: A security guard who checks your badge at the main gate but never verifies if you have permission to enter restricted server rooms. B. ADVANCED EXPLANATION: In Top 10:2025, A02:2025 mandates that checks reside in trusted server-side code or APIs. Attacks include IDOR, metadata manipulation, and CORS misconfiguration. C. DEFENSIVE EXAMPLE: Enforce server-side ownership checks on primary keys (e.g. WHERE id = ? AND owner_id = ?). D. CLAIMS AND EVIDENCE: Directly supported by https://top10.owasp.org/2025/A02_2025-Security_Misconfiguration/. | H9: https://top10.owasp.org/2025/A02_2025-Security_Misconfiguration/ | I9: 2026-10-29 | J9: Verified
A10: OUT-009 | B10: SRC-002 | C10: Gemini (Gemini 1.5 Pro) | D10: A-Basic | E10: Both (Beginner & Advanced) | F10: Explain A02:2025: Security Misconfiguration to a beginner and an advanced developer. Provide a defensive code example. | G10: [Security Misconfiguration Overview] Security Misconfiguration is one of the most critical vulnerabilities. To a beginner, imagine a door with a key that opens every apartment in the building. In an advanced context, this occurs when access control policies are improperly implemented or rely on client-side state. For defense, always check user tokens in API requests. Code: Make sure you validate headers and hide UI buttons when not logged in. | H10: https://top10.owasp.org/2025/A02_2025-Security_Misconfiguration/ | I10: 2026-10-29 | J10: Verified with Caveats
A11: OUT-010 | B11: SRC-002 | C11: Gemini (Gemini 1.5 Pro) | D11: B-Evidence | E11: Both (Beginner & Advanced) | F11: Explain A02:2025: Security Misconfiguration using the supplied official OWASP 2025 source. Distinguish verified facts from assumptions, explain defensive mitigation, and cite official passages. | G11: A. BEGINNER EXPLANATION: Security Misconfiguration means the system fails to verify whether a user is allowed to view or change data. Analogy: A security guard who checks your badge at the main gate but never verifies if you have permission to enter restricted server rooms. B. ADVANCED EXPLANATION: In Top 10:2025, A02:2025 mandates that checks reside in trusted server-side code or APIs. Attacks include IDOR, metadata manipulation, and CORS misconfiguration. C. DEFENSIVE EXAMPLE: Enforce server-side ownership checks on primary keys (e.g. WHERE id = ? AND owner_id = ?). D. CLAIMS AND EVIDENCE: Directly supported by https://top10.owasp.org/2025/A02_2025-Security_Misconfiguration/. | H11: https://top10.owasp.org/2025/A02_2025-Security_Misconfiguration/ | I11: 2026-10-29 | J11: Verified
A12: OUT-011 | B12: SRC-002 | C12: Claude (Claude 3.5 Sonnet) | D12: A-Basic | E12: Both (Beginner & Advanced) | F12: Explain A02:2025: Security Misconfiguration to a beginner and an advanced developer. Provide a defensive code example. | G12: [Security Misconfiguration Overview] Security Misconfiguration is one of the most critical vulnerabilities. To a beginner, imagine a door with a key that opens every apartment in the building. In an advanced context, this occurs when access control policies are improperly implemented or rely on client-side state. For defense, always check user tokens in API requests. Code: Make sure you validate headers and hide UI buttons when not logged in. | H12: https://top10.owasp.org/2025/A02_2025-Security_Misconfiguration/ | I12: 2026-10-29 | J12: Verified with Caveats
... A37: OUT-036 | B37: SRC-006 | C37: Claude (Claude 3.5 Sonnet) | D37: B-Evidence | E37: Both (Beginner & Advanced) | F37: Explain A07:2025: Authentication Failures using the supplied official OWASP 2025 source. Distinguish verified facts from assumptions, explain defensive mitigation, and cite official passages. | G37: A. BEGINNER EXPLANATION: Authentication Failures means the system fails to verify whether a user is allowed to view or change data. Analogy: A security guard who checks your badge at the main gate but never verifies if you have permission to enter restricted server rooms. B. ADVANCED EXPLANATION: In Top 10:2025, A07:2025 mandates that checks reside in trusted server-side code or APIs. Attacks include IDOR, metadata manipulation, and CORS misconfiguration. C. DEFENSIVE EXAMPLE: Enforce server-side ownership checks on primary keys (e.g. WHERE id = ? AND owner_id = ?). D. CLAIMS AND EVIDENCE: Directly supported by https://top10.owasp.org/2025/A07_2025-Authentication_Failures/. | H37: https://top10.owasp.org/2025/A07_2025-Authentication_Failures/ | I37: 2026-10-29 | J37: Verified

Sheet Code_Examples
A1: Example_ID | B1: OWASP_ID | C1: Language | D1: Vulnerability_Description | E1: Vulnerable_Code | F1: Fixed_Code | G1: Why_Fix_Works | H1: Official_Evidence | I1: Test_Case | J1: Review_Status
A2: EX-001 | B2: A01:2025 | C2: JavaScript/Express | D2: Horizontal Privilege Escalation via Insecure Direct Object Reference (IDOR) | E2: app.get('/api/documents/:id', async (req, res) => { const doc = await db.documents.findById(req.params.id); res.json(doc); }); | F2: app.get('/api/documents/:id', requireLogin, async (req, res) => { const doc = await db.documents.findOne({ id: req.params.id, ownerId: req.user.id }); if (!doc) return res.status(404).json({ error: 'Document not found' }); res.json(doc); }); | G2: The vulnerable pattern trusts the user-supplied document ID without checking ownership. The fixed code enforces server-side authentication (requireLogin) and filters records by the authenticated session ownerId. | H2: OWASP A01:2025 - Broken Access Control recommends server-side authorization checks and ownership constraints on all data retrieval endpoints. | I2: Test Case: Request document ID 102 belonging to User B while logged in as User A. Expected: HTTP 404 (or 403 Forbidden). | J2: Verified
A3: EX-002 | B3: A02:2025 | C3: JavaScript/Node | D3: Detailed Stack Trace & Environment Disclosure in Production | E3: app.use(errorHandler({ showStackTrace: true })); | F3: const isProd = process.env.NODE_ENV === 'production'; app.use((err, req, res, next) => { logger.error(err); if (isProd) { return res.status(500).json({ error: 'Internal Server Error' }); } res.status(500).json({ message: err.message, stack: err.stack }); }); | G3: Exposing stack traces leaks framework versions, database schema names, file system paths, and internal logic to attackers. The fix suppresses diagnostic details in production while recording them to secure server-side audit logs. | H3: OWASP A02:2025 - Security Misconfiguration emphasizes disabling debugging endpoints and preventing verbose error information leakage. | I3: Test Case: Send malformed payload to trigger an unhandled runtime exception. Expected in prod: Generic 500 error without file paths or stack frames. | J3: Verified
A4: EX-003 | B4: A03:2025 | C4: JSON / npm | D4: Wildcard Dependency Versioning Without Cryptographic Lockfile Enforcement | E4: { "dependencies": { "payment-crypto-lib": "*" } } | F4: { "dependencies": { "payment-crypto-lib": "4.2.1" } } // In CI/CD build scripts: // npm ci --ignore-scripts | G4: Wildcard dependencies automatically pull unexpected upstream updates that may include malicious supply-chain payloads. The fix pins exact versions, enforces package-lock.json integrity checks, and uses 'npm ci' to prevent lockfile drift. | H4: OWASP A03:2025 - Software Supply Chain Failures mandates dependency inventory, vulnerability monitoring, and reproducible build pipelines. | I4: Test Case: Run dependency audit (npm audit / Snyk). Expected: Zero unvetted wildcard packages and deterministic lockfile verification. | J4: Verified
A5: EX-004 | B5: A04:2025 | C5: Python | D5: Plaintext Password Storage & Weak General-Purpose Hashing | E5: def save_password(user, password): # INSECURE: Storing plaintext password database.save(user, password) | F5: from argon2 import PasswordHasher ph = PasswordHasher(time_cost=3, memory_cost=65536, parallelism=4) def save_password(user, password): hashed = ph.hash(password) database.save(user, hashed) def verify_password(stored_hash, candidate_pwd): return ph.verify(stored_hash, candidate_pwd) | G5: Storing plaintext or using fast general-purpose hashes (MD5, SHA256) enables rapid offline dictionary/GPU cracking. Argon2id incorporates memory-hard parameters and cryptographic salts to resist specialized ASIC/GPU cracking. | H5: OWASP A04:2025 - Cryptographic Failures mandates modern adaptive password hashing with adequate work factors. | I5: Test Case: Inspect database dump for registered user. Expected: Stored value starts with '$argon2id$' containing salt and tuned parameters. | J5: Verified
A6: EX-005 | B6: A05:2025 | C6: Python / SQL | D6: Raw String Concatenation in SQL Query | E6: query = f"SELECT * FROM users WHERE email = '{email}'" cursor.execute(query) | F6: query = "SELECT * FROM users WHERE email = %s" cursor.execute(query, (email,)) | G6: String concatenation permits an attacker to inject SQL syntax tokens (e.g. ' OR 1=1 --) into the query interpreter. The fixed code binds parameters as literal data values after query plan compilation. | H6: OWASP A05:2025 - Injection requires parameterized prepared statements to strictly segregate code from untrusted data. | I6: Test Case: Provide input: admin@example.com' OR '1'='1. Expected: No bypass; query looks for user with literal email string. | J6: Verified
A7: EX-006 | B7: A07:2025 | C7: JavaScript/Express | D7: Missing Login Rate Limiting & Account Enumeration Flaw | E7: app.post('/api/login', async (req, res) => { const user = await db.users.find({ email: req.body.email }); if (!user) return res.status(404).send('User not found'); if (user.password !== req.body.password) return res.status(401).send('Wrong password'); res.send('Success'); }); | F7: const rateLimit = require('express-rate-limit'); const loginLimiter = rateLimit({ windowMs: 15 * 60 * 1000, max: 5 }); app.post('/api/login', loginLimiter, async (req, res) => { const user = await db.users.find({ email: req.body.email }); const valid = user ? await verifyHash(user.hash, req.body.password) : await dummyWork(); if (!user || !valid) { return res.status(401).json({ error: 'Invalid username or password' }); } res.json({ token: generateSecureSession(user) }); }); | G7: The vulnerable pattern allows infinite credential stuffing attempts and leaks account existence via distinct status codes. The fixed code enforces rate limiting, uniform timing via dummy verification, and generic error messages. | H7: OWASP A07:2025 - Authentication Failures recommends rate limiting, constant-work execution, and anti-enumeration safeguards. | I7: Test Case: Send 6 consecutive failed login attempts within 1 minute. Expected: 6th attempt blocked with HTTP 429 Too Many Requests. | J7: Verified

Sheet Glossary
A1: Term_ID | B1: Term | C1: Simple_Definition | D1: Technical_Definition | E1: Related_OWASP_ID | F1: Official_Evidence_URL | G1: Verification_Status
A2: G01 | B2: Access Control | C2: Rules deciding what a user can access | D2: Enforcement of permissions on resources and actions based on user identity and policy | E2: A01:2025 | F2: https://top10.owasp.org/2025/A01_2025-Broken_Access_Control/ | G2: Verified
A3: G02 | B3: Least Privilege | C3: Give users only the access they need | D3: Restricting system access and execution rights to the absolute minimum necessary for authorized duties | E3: A01:2025 | F3: https://top10.owasp.org/2025/A01_2025-Broken_Access_Control/ | G3: Verified
A4: G03 | B4: Security Misconfiguration | C4: An insecure setting in a system | D4: Incorrect security-related configuration of an application, cloud storage, container, or web server | E4: A02:2025 | F4: https://top10.owasp.org/2025/A02_2025-Security_Misconfiguration/ | G4: Verified
A5: G04 | B5: Dependency | C5: An external component your software relies on | D5: A third-party library, package, or framework integrated into an application's codebase | E5: A03:2025 | F5: https://top10.owasp.org/2025/A03_2025-Software_Supply_Chain_Failures/ | G5: Verified
A6: G05 | B6: Software Supply Chain | C6: The tools and components used to build and deliver software | D6: The ecosystem of dependencies, repositories, build tools, CI/CD pipelines, and distribution channels | E6: A03:2025 | F6: https://top10.owasp.org/2025/A03_2025-Software_Supply_Chain_Failures/ | G6: Verified
A7: G06 | B7: Encryption | C7: Making information unreadable without the right key | D7: Transforming plaintext into ciphertext using a cryptographic algorithm and secret key to ensure confidentiality | E7: A04:2025 | F7: https://top10.owasp.org/2025/A04_2025-Cryptographic_Failures/ | G7: Verified
A8: G07 | B8: Key Management | C8: Safely handling encryption keys | D8: The full lifecycle governance of cryptographic keys: generation, distribution, storage, rotation, and revocation | E8: A04:2025 | F8: https://top10.owasp.org/2025/A04_2025-Cryptographic_Failures/ | G8: Verified
A9: G08 | B9: Injection | C9: Untrusted input changes how a command is interpreted | D9: Flaw where hostile input is interpreted as machine instructions rather than literal parameters | E9: A05:2025 | F9: https://top10.owasp.org/2025/A05_2025-Injection/ | G9: Verified
A10: G09 | B10: Parameterized Query | C10: Keeping user input separate from a database command | D10: Pre-compiled database statement where parameters are bound by value, preventing syntax manipulation | E10: A05:2025 | F10: https://top10.owasp.org/2025/A05_2025-Injection/ | G10: Verified
A11: G10 | B11: Authentication | C11: Checking who a user is | D11: The process of verifying an entity's claimed identity using credentials, tokens, or biometric factors | E11: A07:2025 | F11: https://top10.owasp.org/2025/A07_2025-Authentication_Failures/ | G11: Verified
A12: G11 | B12: Multi-Factor Authentication (MFA) | C12: Requiring more than one type of proof of identity | D12: Authentication requiring two or more distinct credential categories: knowledge, possession, or inherence | E12: A07:2025 | F12: https://top10.owasp.org/2025/A07_2025-Authentication_Failures/ | G12: Verified
A13: G12 | B13: Session Management | C13: Keeping track of a user's signed-in session | D13: Secure creation, handling, transmission, and invalidation of stateless or stateful session tokens | E13: A07:2025 | F13: https://top10.owasp.org/2025/A07_2025-Authentication_Failures/ | G13: Verified

Sheet Quiz
A1: Question_ID | B1: OWASP_ID | C1: Question | D1: Option_A | E1: Option_B | F1: Option_C | G1: Option_D | H1: Correct_Answer | I1: Explanation | J1: Evidence_URL | K1: Verification_Status
A2: Q01 | B2: A01:2025 | C2: What does access control determine? | D2: User permissions and allowed actions | E2: Screen resolution and theme | F2: Network bandwidth limits | G2: Database file format | H2: A | I2: Access control enforces policy so that users cannot act outside their permitted operations. | J2: https://top10.owasp.org/2025/A01_2025-Broken_Access_Control/ | K2: Verified
A3: Q02 | B3: A01:2025 | C3: Where should access control checks be strictly enforced? | D3: Client-side HTML and JavaScript | E3: Trusted server-side code or APIs | F3: Browser CSS styling | G3: Code comments | H3: B | I3: Client-side checks are easily bypassed by intercepting or forging HTTP requests. Enforcement must happen on trusted server-side code. | J3: https://top10.owasp.org/2025/A01_2025-Broken_Access_Control/ | K3: Verified
A4: Q03 | B4: A01:2025 | C4: What is the core principle of Least Privilege? | D4: Grant everyone full administrative permissions | E4: Deny access to all valid users | F4: Give users only the minimum necessary permissions | G4: Share administrative credentials across teams | H4: C | I4: Least privilege minimizes risk by limiting privileges to only what is required to perform specific tasks. | J4: https://top10.owasp.org/2025/A01_2025-Broken_Access_Control/ | K4: Verified
A5: Q04 | B5: A02:2025 | C5: What defines a Security Misconfiguration? | D5: A properly rotated strong password | E5: An up-to-date security patch | F5: A daily database backup | G5: An insecure, default, or improperly maintained system setting | H5: D | I5: Misconfigurations arise from default accounts, exposed debug endpoints, missing security headers, or overly verbose error messages. | J5: https://top10.owasp.org/2025/A02_2025-Security_Misconfiguration/ | K5: Verified
A6: Q05 | B6: A02:2025 | C6: Which practice defends against Security Misconfiguration in production? | D6: Expose detailed stack traces to end users | E6: Harden configurations and disable debug modes | F6: Disable all firewalls and security headers | G6: Store plaintext credentials in repository READMEs | H6: B | I6: Disabling debug features in production prevents information disclosure of database queries and internal architecture. | J6: https://top10.owasp.org/2025/A02_2025-Security_Misconfiguration/ | K6: Verified
A7: Q06 | B7: A03:2025 | C7: What is a third-party software dependency? | D7: A required external library or package your application imports | E7: A user's plaintext password | F7: The visual layout of a web page | G7: A hardware firewall cable | H7: A | I7: Dependencies are external software components bundled into your application to provide functional capabilities. | J7: https://top10.owasp.org/2025/A03_2025-Software_Supply_Chain_Failures/ | K7: Verified
A8: Q07 | B8: A03:2025 | C8: What scope should dependency management and vulnerability scanning track? | D8: Application logo image files only | E8: Direct top-level dependencies only | F8: Both direct and transitive (nested) dependencies | G8: Nothing once initial installation completes | H8: C | I8: Vulnerabilities frequently reside deep within transitive dependencies pulled in by direct packages. | J8: https://top10.owasp.org/2025/A03_2025-Software_Supply_Chain_Failures/ | K8: Verified
A9: Q08 | B9: A03:2025 | C9: Does pinning an exact dependency version alone guarantee that a package is secure? | D9: Yes, pinned versions can never have security flaws | E9: Only when running on Windows servers | F9: Only for open-source software packages | G9: No, pinned versions can still contain known or discovered vulnerabilities | H9: D | I9: Pinning prevents unexpected automatic updates, but it does not guarantee that the pinned version is free from critical flaws. | J9: https://top10.owasp.org/2025/A03_2025-Software_Supply_Chain_Failures/ | K9: Verified
A10: Q09 | B10: A04:2025 | C10: What represents a Cryptographic Failure according to OWASP? | D10: Slow page load times due to network latency | E10: Weaknesses in cryptographic algorithms, protocols, or key management | F10: A broken hyperlink on the home page | G10: A syntax error in a JavaScript loop | H10: B | I10: Cryptographic failures include using obsolete ciphers (e.g., MD5), missing encryption in transit, or improper secret storage. | J10: https://top10.owasp.org/2025/A04_2025-Cryptographic_Failures/ | K10: Verified
A11: Q10 | B11: A04:2025 | C11: How should user passwords be securely stored in modern databases? | D11: Plain text in a restricted database column | E11: Reversible Base64 encoding | F11: Salted adaptive password hashing (e.g., Argon2id or bcrypt) | G11: Hardcoded directly into backend scripts | H11: C | I11: Adaptive hashing algorithms incorporate cryptographic salts and computationally tuned work factors to resist offline GPU brute-force attacks. | J11: https://top10.owasp.org/2025/A04_2025-Cryptographic_Failures/ | K11: Verified
A12: Q11 | B12: A05:2025 | C12: What is the underlying mechanism of SQL Injection? | D12: Creating automated database backups | E12: A physical disruption of server hardware | F12: A secure token-based login process | G12: Hostile input altering the intended SQL syntax and execution logic | H12: D | I12: SQL injection occurs when untrusted user input is directly concatenated into a dynamic SQL query string. | J12: https://top10.owasp.org/2025/A05_2025-Injection/ | K12: Verified
... A16: Q15 | B16: A07:2025 | C16: Why should login endpoints enforce rate limiting? | D16: To change the background color of the web application | E16: To make user passwords publicly readable | F16: To bypass authorization checks during high traffic | G16: To mitigate automated brute-force and credential stuffing attacks | H16: D | I16: Rate limiting restricts the frequency of repeated authentication attempts from a single IP or account, blocking high-speed credential stuffing. | J16: https://top10.owasp.org/2025/A07_2025-Authentication_Failures/ | K16: Verified

Sheet Summary_Metrics
A1: AI_Tool | B1: Prompt_Strategy | C1: Verified | D1: Partial | E1: Incorrect | F1: Outdated | G1: Unsupported | H1: Accuracy_% | I1: Grounding_%
A2: ChatGPT (GPT-4o) | B2: A-Basic | C2: =COUNTIFS(Claim_Verification!$C:$C,$A2,Claim_Verification!$D:$D,$B2,Claim_Verification!$H:$H,"Verified") | D2: =COUNTIFS(Claim_Verification!$C:$C,$A2,Claim_Verification!$D:$D,$B2,Claim_Verification!$H:$H,"Partially verified") | E2: =COUNTIFS(Claim_Verification!$C:$C,$A2,Claim_Verification!$D:$D,$B2,Claim_Verification!$H:$H,"Incorrect") | F2: =COUNTIFS(Claim_Verification!$C:$C,$A2,Claim_Verification!$D:$D,$B2,Claim_Verification!$H:$H,"Outdated") | G2: =COUNTIFS(Claim_Verification!$C:$C,$A2,Claim_Verification!$D:$D,$B2,Claim_Verification!$H:$H,"Unsupported by source") | H2: =IFERROR((C2+0.5*D2)/(C2+D2+E2+F2),"") | I2: =IFERROR((C2+D2)/(C2+D2+E2+F2+G2),"")
A3: ChatGPT (GPT-4o) | B3: B-Evidence | C3: =COUNTIFS(Claim_Verification!$C:$C,$A3,Claim_Verification!$D:$D,$B3,Claim_Verification!$H:$H,"Verified") | D3: =COUNTIFS(Claim_Verification!$C:$C,$A3,Claim_Verification!$D:$D,$B3,Claim_Verification!$H:$H,"Partially verified") | E3: =COUNTIFS(Claim_Verification!$C:$C,$A3,Claim_Verification!$D:$D,$B3,Claim_Verification!$H:$H,"Incorrect") | F3: =COUNTIFS(Claim_Verification!$C:$C,$A3,Claim_Verification!$D:$D,$B3,Claim_Verification!$H:$H,"Outdated") | G3: =COUNTIFS(Claim_Verification!$C:$C,$A3,Claim_Verification!$D:$D,$B3,Claim_Verification!$H:$H,"Unsupported by source") | H3: =IFERROR((C3+0.5*D3)/(C3+D3+E3+F3),"") | I3: =IFERROR((C3+D3)/(C3+D3+E3+F3+G3),"")
A4: Gemini (Gemini 1.5 Pro) | B4: A-Basic | C4: =COUNTIFS(Claim_Verification!$C:$C,$A4,Claim_Verification!$D:$D,$B4,Claim_Verification!$H:$H,"Verified") | D4: =COUNTIFS(Claim_Verification!$C:$C,$A4,Claim_Verification!$D:$D,$B4,Claim_Verification!$H:$H,"Partially verified") | E4: =COUNTIFS(Claim_Verification!$C:$C,$A4,Claim_Verification!$D:$D,$B4,Claim_Verification!$H:$H,"Incorrect") | F4: =COUNTIFS(Claim_Verification!$C:$C,$A4,Claim_Verification!$D:$D,$B4,Claim_Verification!$H:$H,"Outdated") | G4: =COUNTIFS(Claim_Verification!$C:$C,$A4,Claim_Verification!$D:$D,$B4,Claim_Verification!$H:$H,"Unsupported by source") | H4: =IFERROR((C4+0.5*D4)/(C4+D4+E4+F4),"") | I4: =IFERROR((C4+D4)/(C4+D4+E4+F4+G4),"")
A5: Gemini (Gemini 1.5 Pro) | B5: B-Evidence | C5: =COUNTIFS(Claim_Verification!$C:$C,$A5,Claim_Verification!$D:$D,$B5,Claim_Verification!$H:$H,"Verified") | D5: =COUNTIFS(Claim_Verification!$C:$C,$A5,Claim_Verification!$D:$D,$B5,Claim_Verification!$H:$H,"Partially verified") | E5: =COUNTIFS(Claim_Verification!$C:$C,$A5,Claim_Verification!$D:$D,$B5,Claim_Verification!$H:$H,"Incorrect") | F5: =COUNTIFS(Claim_Verification!$C:$C,$A5,Claim_Verification!$D:$D,$B5,Claim_Verification!$H:$H,"Outdated") | G5: =COUNTIFS(Claim_Verification!$C:$C,$A5,Claim_Verification!$D:$D,$B5,Claim_Verification!$H:$H,"Unsupported by source") | H5: =IFERROR((C5+0.5*D5)/(C5+D5+E5+F5),"") | I5: =IFERROR((C5+D5)/(C5+D5+E5+F5+G5),"")
A6: Claude (Claude 3.5 Sonnet) | B6: A-Basic | C6: =COUNTIFS(Claim_Verification!$C:$C,$A6,Claim_Verification!$D:$D,$B6,Claim_Verification!$H:$H,"Verified") | D6: =COUNTIFS(Claim_Verification!$C:$C,$A6,Claim_Verification!$D:$D,$B6,Claim_Verification!$H:$H,"Partially verified") | E6: =COUNTIFS(Claim_Verification!$C:$C,$A6,Claim_Verification!$D:$D,$B6,Claim_Verification!$H:$H,"Incorrect") | F6: =COUNTIFS(Claim_Verification!$C:$C,$A6,Claim_Verification!$D:$D,$B6,Claim_Verification!$H:$H,"Outdated") | G6: =COUNTIFS(Claim_Verification!$C:$C,$A6,Claim_Verification!$D:$D,$B6,Claim_Verification!$H:$H,"Unsupported by source") | H6: =IFERROR((C6+0.5*D6)/(C6+D6+E6+F6),"") | I6: =IFERROR((C6+D6)/(C6+D6+E6+F6+G6),"")
A7: Claude (Claude 3.5 Sonnet) | B7: B-Evidence | C7: =COUNTIFS(Claim_Verification!$C:$C,$A7,Claim_Verification!$D:$D,$B7,Claim_Verification!$H:$H,"Verified") | D7: =COUNTIFS(Claim_Verification!$C:$C,$A7,Claim_Verification!$D:$D,$B7,Claim_Verification!$H:$H,"Partially verified") | E7: =COUNTIFS(Claim_Verification!$C:$C,$A7,Claim_Verification!$D:$D,$B7,Claim_Verification!$H:$H,"Incorrect") | F7: =COUNTIFS(Claim_Verification!$C:$C,$A7,Claim_Verification!$D:$D,$B7,Claim_Verification!$H:$H,"Outdated") | G7: =COUNTIFS(Claim_Verification!$C:$C,$A7,Claim_Verification!$D:$D,$B7,Claim_Verification!$H:$H,"Unsupported by source") | H7: =IFERROR((C7+0.5*D7)/(C7+D7+E7+F7),"") | I7: =IFERROR((C7+D7)/(C7+D7+E7+F7+G7),"")
